Workbook

Sheet dashboard
A1: 海外社媒热点短剧题材雷达
A2: 第一阶段：英语市场（US/UK/CA/AU）+ 公开可抓数据 + 半自动周监测。评分用于选题优先级，不等同于立项结论。
A4: 模块 | B4: 口径 | C4: 当前值 | E4: 评分维度 | F4: 权重
A5: 覆盖市场 | B5: 默认国家/地区 | C5: US, UK, CA, AU | E5: 热度 | F5: 35
A6: 数据边界 | B6: 公开趋势/搜索/帖子/视频，不采集登录态和私密内容 | C6: Public only | E6: 情绪强度 | F6: 25
A7: 周监测节奏 | B7: 每周一回看过去 7 天 | C7: Weekly | E7: 题材可短剧化 | F7: 20
A8: 候选输出 | B8: 3 个高优先级 + 4 个观察级 + 3 个风险苗头 | C8: Top 10 | E8: 供给缺口 | F8: 10
A9: 评分公式 | B9: 热度35 + 情绪25 + 可短剧化20 + 供给缺口10 - 风险10 | C9: 100 pts | E9: 合规/品牌风险扣分 | F9: 10
A12: Top 候选题材 | B12: 优先级 | C12: 机会分 | D12: 建议动作 | E12: 核心理由
A13: =weekly_watchlist!$C$5 | B13: =weekly_watchlist!$D$5 | C13: =weekly_watchlist!$F$5 | D13: =weekly_watchlist!$J$5 | E13: =weekly_watchlist!$I$5
A14: =weekly_watchlist!$C$6 | B14: =weekly_watchlist!$D$6 | C14: =weekly_watchlist!$F$6 | D14: =weekly_watchlist!$J$6 | E14: =weekly_watchlist!$I$6
A15: =weekly_watchlist!$C$7 | B15: =weekly_watchlist!$D$7 | C15: =weekly_watchlist!$F$7 | D15: =weekly_watchlist!$J$7 | E15: =weekly_watchlist!$I$7
A16: =weekly_watchlist!$C$8 | B16: =weekly_watchlist!$D$8 | C16: =weekly_watchlist!$F$8 | D16: =weekly_watchlist!$J$8 | E16: =weekly_watchlist!$I$8
A17: =weekly_watchlist!$C$9 | B17: =weekly_watchlist!$D$9 | C17: =weekly_watchlist!$F$9 | D17: =weekly_watchlist!$J$9 | E17: =weekly_watchlist!$I$9
A20: 每周一执行清单 | B20: 说明
A21: 1. 抓取过去 7 天热点 | B21: TikTok Creative Center、Google Trends、YouTube Trending/Charts、Reddit 公开热帖。
A22: 2. 填入 raw_signals | B22: 保留公开链接、摘要、地区、互动/排名指标、情绪标签和证据等级。
A23: 3. 合并 topic_clusters | B23: 把同一热点的不同关键词/平台信号归并成一个题材簇。
A24: 4. 映射 drama_angle_map | B24: 用短剧题材、可能 logline、制作适配和风险说明判断可转化性。
A25: 5. 更新 weekly_watchlist | B25: 输出 10 个候选：高优先级、观察级、风险苗头。

Sheet raw_signals
A1: raw_signals
A2: 逐条记录公开社媒/趋势信号。只保留公开链接、聚合指标和必要文本摘要。
A4: date | B4: source_platform | C4: country_region | D4: language | E4: keyword_or_hashtag | F4: post_title_or_caption | G4: url | H4: views_or_rank | I4: likes | J4: comments | K4: shares | L4: trend_window | M4: sentiment | N4: emotion_tags | O4: evidence_level | P4: last_checked | Q4: notes
A5: 46182 | B5: Google Trends | C5: US | D5: EN | E5: single mom comeback | F5: Search interest around single mom success / revenge narratives | G5: https://trends.google.com/trends/trendingsearches/daily?geo=US | H5: rank/watch | L5: 7d | M5: positive | N5: resilience,revenge,empathy | O5: B | P5: 46182 | Q5: 泛热点，需二次核验
A6: 46182 | B6: TikTok Creative Center | C6: US | D6: EN | E6: #cheatingstory | F6: Relationship betrayal storytime hooks and confession-style videos | G6: https://ads.tiktok.com/business/creativecenter/inspiration/popular/hashtag | H6: rank/watch | L6: 7d | M6: negative | N6: anger,betrayal,curiosity | O6: B | P6: 46182 | Q6: 适合情感背叛/复仇爽感
A7: 46182 | B7: Reddit | C7: US | D7: EN | E7: toxic relationship | F7: Advice threads around emotional manipulation and breakup recovery | G7: https://www.reddit.com/search/?q=toxic%20relationship | H7: score/comments | L7: 7d | M7: negative | N7: anger,fear,healing | O7: B | P7: 46182 | Q7: 只采公开帖摘要
A8: 46182 | B8: YouTube | C8: US | D8: EN | E8: workplace drama | F8: Trending workplace conflict / unfair boss narratives | G8: https://www.youtube.com/feed/trending | H8: rank/watch | L8: 7d | M8: mixed | N8: frustration,justice | O8: B | P8: 46182 | Q8: 职场压迫和逆袭可转化
A9: 46182 | B9: TikTok Creative Center | C9: UK | D9: EN | E9: mafia romance | F9: Romance fantasy hooks with danger / forbidden-love framing | G9: https://ads.tiktok.com/business/creativecenter/inspiration/popular/hashtag | H9: rank/watch | L9: 7d | M9: mixed | N9: desire,danger,suspense | O9: C | P9: 46182 | Q9: 题材强但风险需标注
A10: 46182 | B10: Google Trends | C10: AU | D10: EN | E10: werewolf mate | F10: Fantasy romance search pattern tied to soulmate / rejection arcs | G10: https://trends.google.com/trends/explore?geo=AU&q=werewolf%20mate | H10: search interest | L10: 7d | M10: positive | N10: fantasy,longing,rejection | O10: C | P10: 46182 | Q10: 与现有短剧强类型重合
A11: 46182 | B11: Instagram | C11: US | D11: EN | E11: tradwife backlash | F11: Public hashtag/search direction around traditional-wife identity, backlash, and relationship role debates. | G11: https://www.instagram.com/explore/tags/tradwife/ | H11: public hashtag/search | L11: 7d | M11: mixed | N11: identity,gender_roles,backlash | O11: C | P11: 46182 | Q11: 潜力题材：身份叙事/亲密关系角色争议，待核验热度
A12: 46182 | B12: X / Twitter | C12: US | D12: EN | E12: AI girlfriend breakup | F12: Public search direction around AI companion relationships and emotional dependency. | G12: https://x.com/search?q=%22AI%20girlfriend%22&src=typed_query&f=top | H12: public search | L12: 7d | M12: mixed | N12: loneliness,dependency,technology | O12: C | P12: 46182 | Q12: 潜力题材：AI亲密关系/孤独经济，暂不映射现有短剧类型
A13: 46182 | B13: Quora | C13: US | D13: EN | E13: dating after divorce | F13: Question/search direction around second-chance romance, trust rebuilding, and late-life dating. | G13: https://www.quora.com/search?q=dating%20after%20divorce | H13: public search | L13: 7d | M13: mixed | N13: second_chance,trust,healing | O13: C | P13: 46182 | Q13: 潜力题材：熟龄二次恋爱/信任重建，待观察
A14: 46182 | B14: Medium | C14: US | D14: EN | E14: loneliness economy | F14: Essay/search direction around loneliness, emotional services, and modern intimacy. | G14: https://medium.com/search?q=loneliness%20economy | H14: public search | L14: 7d | M14: negative | N14: loneliness,modern_life,emotional_need | O14: C | P14: 46182 | Q14: 潜力题材：孤独经济/情感服务，偏新方向

Sheet topic_clusters
A1: topic_clusters
A2: 把多平台、多关键词信号归并为题材簇，并给出 0-100 的分项评分。
A4: cluster_name | B4: trigger_event | C4: audience_pain_point | D4: dominant_emotion | E4: related_keywords | F4: platforms_seen | G4: heat_score | H4: sentiment_score | I4: novelty_score | J4: sustainability_score
A5: Single mom comeback | B5: Single mom / independence / payback narratives rising | C5: 被低估、被抛弃后重新掌控人生 | D5: resilience | E5: single mom comeback; abandoned wife; custody battle | F5: Google Trends,TikTok | G5: 76 | H5: 72 | I5: 62 | J5: 68
A6: Cheating revenge storytime | B6: Confession and betrayal storytime hooks trend | C6: 亲密关系背叛后的愤怒与复仇期待 | D6: anger | E6: #cheatingstory; betrayal; revenge | F6: TikTok,Reddit | G6: 84 | H6: 86 | I6: 55 | J6: 61
A7: Toxic relationship recovery | B7: Advice/discussion threads around manipulation and breakup | C7: 情感操控、PUA、逃离关系后的自我修复 | D7: healing | E7: toxic relationship; gaslighting; breakup recovery | F7: Reddit,TikTok | G7: 69 | H7: 80 | I7: 57 | J7: 74
A8: Workplace justice arc | B8: Unfair boss and workplace conflict content continues to circulate | C8: 职场压迫、阶层不平等、迟来的正义 | D8: frustration | E8: workplace drama; bad boss; fired unfairly | F8: YouTube,TikTok,Reddit | G8: 64 | H8: 66 | I8: 58 | J8: 72
A9: Mafia forbidden romance | B9: Dangerous romance and forbidden-love hooks | C9: 高风险关系里的安全感、欲望与权力幻想 | D9: desire | E9: mafia romance; forbidden love; dangerous boyfriend | F9: TikTok | G9: 58 | H9: 74 | I9: 51 | J9: 60
A10: Werewolf rejected mate | B10: Fantasy soulmate/rejection arcs show durable demand | C10: 被命定伴侣拒绝后的逆袭与再选择 | D10: longing | E10: werewolf mate; rejected mate; alpha romance | F10: Google Trends,TikTok | G10: 62 | H10: 69 | I10: 42 | J10: 76

Sheet drama_angle_map
A1: drama_angle_map
A2: 将题材簇翻译成短剧角度，并用公式计算机会分。
A4: topic_cluster | B4: short_drama_genre | C4: possible_logline | D4: target_audience | E4: reference_titles | F4: production_fit | G4: risk_notes | H4: opportunity_score
A5: Single mom comeback | B5: 女性成长 / 家庭伦理 / 逆袭 | C5: A discarded single mother rebuilds her life, wins custody, and exposes the billionaire ex who tried to erase her. | D5: Women 25-44, romance/revenge viewers | E5: ReelShort/DramaBox romance-revenge baseline | F5: High: live-action, low VFX, strong hook density | G5: Low: avoid exploiting custody/legal trauma | H5: =IF($A$5="","",ROUND(0.35*VLOOKUP($A$5,topic_clusters!$A$5:$J$104,7,FALSE)+0.25*VLOOKUP($A$5,topic_clusters!$A$5:$J$104,8,FALSE)+0.2*VLOOKUP($A$5,topic_clusters!$A$5:$J$104,9,FALSE)+0.1*VLOOKUP($A$5,topic_clusters!$A$5:$J$104,10,FALSE)-10*IF(ISNUMBER(SEARCH("High",$G$5)),1,IF(ISNUMBER(SEARCH("Medium",$G$5)),0.5,0)),0))
A6: Cheating revenge storytime | B6: 情感背叛 / 复仇爽感 | C6: After catching her fiance cheating before the wedding, a quiet bride allies with his rival and takes back the family empire. | D6: Women 18-44, relationship storytime audience | E6: Romance revenge / betrayal arcs | F6: High: modern romance, high cliffhanger fit | G6: Medium: avoid defamatory real-person parallels | H6: =IF($A$6="","",ROUND(0.35*VLOOKUP($A$6,topic_clusters!$A$5:$J$104,7,FALSE)+0.25*VLOOKUP($A$6,topic_clusters!$A$5:$J$104,8,FALSE)+0.2*VLOOKUP($A$6,topic_clusters!$A$5:$J$104,9,FALSE)+0.1*VLOOKUP($A$6,topic_clusters!$A$5:$J$104,10,FALSE)-10*IF(ISNUMBER(SEARCH("High",$G$6)),1,IF(ISNUMBER(SEARCH("Medium",$G$6)),0.5,0)),0))
A7: Toxic relationship recovery | B7: 女性成长 / 心理悬疑 | C7: A woman escapes a charming manipulator, only to discover his next target is her younger sister. | D7: Women 18-40, advice/community discussion users | E7: Suspense-romance hybrid | F7: Medium: needs careful tone and empathy | G7: Medium: domestic abuse depiction sensitivity | H7: =IF($A$7="","",ROUND(0.35*VLOOKUP($A$7,topic_clusters!$A$5:$J$104,7,FALSE)+0.25*VLOOKUP($A$7,topic_clusters!$A$5:$J$104,8,FALSE)+0.2*VLOOKUP($A$7,topic_clusters!$A$5:$J$104,9,FALSE)+0.1*VLOOKUP($A$7,topic_clusters!$A$5:$J$104,10,FALSE)-10*IF(ISNUMBER(SEARCH("High",$G$7)),1,IF(ISNUMBER(SEARCH("Medium",$G$7)),0.5,0)),0))
A8: Workplace justice arc | B8: 职场压迫 / 阶层逆袭 | C8: A fired assistant secretly becomes the investor who decides whether her abusive boss survives the merger. | D8: Women and workplace drama viewers | E8: Urban revenge / career comeback | F8: High: office locations, clear social conflict | G8: Low: keep employment claims fictional | H8: =IF($A$8="","",ROUND(0.35*VLOOKUP($A$8,topic_clusters!$A$5:$J$104,7,FALSE)+0.25*VLOOKUP($A$8,topic_clusters!$A$5:$J$104,8,FALSE)+0.2*VLOOKUP($A$8,topic_clusters!$A$5:$J$104,9,FALSE)+0.1*VLOOKUP($A$8,topic_clusters!$A$5:$J$104,10,FALSE)-10*IF(ISNUMBER(SEARCH("High",$G$8)),1,IF(ISNUMBER(SEARCH("Medium",$G$8)),0.5,0)),0))
A9: Mafia forbidden romance | B9: 禁忌恋 / 黑帮言情 | C9: A cautious nurse saves a wounded mafia heir and is pulled into a contract romance that becomes a war for trust. | D9: Romance fantasy readers/viewers | E9: Mafia romance / contract love | F9: Medium: strong hooks, but needs stylized production | G9: High: violence, coercion, brand-safety risk | H9: =IF($A$9="","",ROUND(0.35*VLOOKUP($A$9,topic_clusters!$A$5:$J$104,7,FALSE)+0.25*VLOOKUP($A$9,topic_clusters!$A$5:$J$104,8,FALSE)+0.2*VLOOKUP($A$9,topic_clusters!$A$5:$J$104,9,FALSE)+0.1*VLOOKUP($A$9,topic_clusters!$A$5:$J$104,10,FALSE)-10*IF(ISNUMBER(SEARCH("High",$G$9)),1,IF(ISNUMBER(SEARCH("Medium",$G$9)),0.5,0)),0))
A10: Werewolf rejected mate | B10: 狼人 / 吸血鬼 / 奇幻言情 | C10: Rejected by her alpha mate, an omega discovers a hidden bloodline and becomes the only person who can stop a pack war. | D10: YA/new adult fantasy romance viewers | E10: Werewolf mate / alpha romance | F10: Medium: AI/VFX or motion-comic friendly | G10: Medium: category crowded; needs twist | H10: =IF($A$10="","",ROUND(0.35*VLOOKUP($A$10,topic_clusters!$A$5:$J$104,7,FALSE)+0.25*VLOOKUP($A$10,topic_clusters!$A$5:$J$104,8,FALSE)+0.2*VLOOKUP($A$10,topic_clusters!$A$5:$J$104,9,FALSE)+0.1*VLOOKUP($A$10,topic_clusters!$A$5:$J$104,10,FALSE)-10*IF(ISNUMBER(SEARCH("High",$G$10)),1,IF(ISNUMBER(SEARCH("Medium",$G$10)),0.5,0)),0))
H11: =IF($A$11="","",ROUND(0.35*VLOOKUP($A$11,topic_clusters!$A$5:$J$104,7,FALSE)+0.25*VLOOKUP($A$11,topic_clusters!$A$5:$J$104,8,FALSE)+0.2*VLOOKUP($A$11,topic_clusters!$A$5:$J$104,9,FALSE)+0.1*VLOOKUP($A$11,topic_clusters!$A$5:$J$104,10,FALSE)-10*IF(ISNUMBER(SEARCH("High",$G$11)),1,IF(ISNUMBER(SEARCH("Medium",$G$11)),0.5,0)),0))
H12: =IF($A$12="","",ROUND(0.35*VLOOKUP($A$12,topic_clusters!$A$5:$J$104,7,FALSE)+0.25*VLOOKUP($A$12,topic_clusters!$A$5:$J$104,8,FALSE)+0.2*VLOOKUP($A$12,topic_clusters!$A$5:$J$104,9,FALSE)+0.1*VLOOKUP($A$12,topic_clusters!$A$5:$J$104,10,FALSE)-10*IF(ISNUMBER(SEARCH("High",$G$12)),1,IF(ISNUMBER(SEARCH("Medium",$G$12)),0.5,0)),0))
H13: =IF($A$13="","",ROUND(0.35*VLOOKUP($A$13,topic_clusters!$A$5:$J$104,7,FALSE)+0.25*VLOOKUP($A$13,topic_clusters!$A$5:$J$104,8,FALSE)+0.2*VLOOKUP($A$13,topic_clusters!$A$5:$J$104,9,FALSE)+0.1*VLOOKUP($A$13,topic_clusters!$A$5:$J$104,10,FALSE)-10*IF(ISNUMBER(SEARCH("High",$G$13)),1,IF(ISNUMBER(SEARCH("Medium",$G$13)),0.5,0)),0))
H14: =IF($A$14="","",ROUND(0.35*VLOOKUP($A$14,topic_clusters!$A$5:$J$104,7,FALSE)+0.25*VLOOKUP($A$14,topic_clusters!$A$5:$J$104,8,FALSE)+0.2*VLOOKUP($A$14,topic_clusters!$A$5:$J$104,9,FALSE)+0.1*VLOOKUP($A$14,topic_clusters!$A$5:$J$104,10,FALSE)-10*IF(ISNUMBER(SEARCH("High",$G$14)),1,IF(ISNUMBER(SEARCH("Medium",$G$14)),0.5,0)),0))
H15: =IF($A$15="","",ROUND(0.35*VLOOKUP($A$15,topic_clusters!$A$5:$J$104,7,FALSE)+0.25*VLOOKUP($A$15,topic_clusters!$A$5:$J$104,8,FALSE)+0.2*VLOOKUP($A$15,topic_clusters!$A$5:$J$104,9,FALSE)+0.1*VLOOKUP($A$15,topic_clusters!$A$5:$J$104,10,FALSE)-10*IF(ISNUMBER(SEARCH("High",$G$15)),1,IF(ISNUMBER(SEARCH("Medium",$G$15)),0.5,0)),0))
H16: =IF($A$16="","",ROUND(0.35*VLOOKUP($A$16,topic_clusters!$A$5:$J$104,7,FALSE)+0.25*VLOOKUP($A$16,topic_clusters!$A$5:$J$104,8,FALSE)+0.2*VLOOKUP($A$16,topic_clusters!$A$5:$J$104,9,FALSE)+0.1*VLOOKUP($A$16,topic_clusters!$A$5:$J$104,10,FALSE)-10*IF(ISNUMBER(SEARCH("High",$G$16)),1,IF(ISNUMBER(SEARCH("Medium",$G$16)),0.5,0)),0))
H17: =IF($A$17="","",ROUND(0.35*VLOOKUP($A$17,topic_clusters!$A$5:$J$104,7,FALSE)+0.25*VLOOKUP($A$17,topic_clusters!$A$5:$J$104,8,FALSE)+0.2*VLOOKUP($A$17,topic_clusters!$A$5:$J$104,9,FALSE)+0.1*VLOOKUP($A$17,topic_clusters!$A$5:$J$104,10,FALSE)-10*IF(ISNUMBER(SEARCH("High",$G$17)),1,IF(ISNUMBER(SEARCH("Medium",$G$17)),0.5,0)),0))
H18: =IF($A$18="","",ROUND(0.35*VLOOKUP($A$18,topic_clusters!$A$5:$J$104,7,FALSE)+0.25*VLOOKUP($A$18,topic_clusters!$A$5:$J$104,8,FALSE)+0.2*VLOOKUP($A$18,topic_clusters!$A$5:$J$104,9,FALSE)+0.1*VLOOKUP($A$18,topic_clusters!$A$5:$J$104,10,FALSE)-10*IF(ISNUMBER(SEARCH("High",$G$18)),1,IF(ISNUMBER(SEARCH("Medium",$G$18)),0.5,0)),0))
H19: =IF($A$19="","",ROUND(0.35*VLOOKUP($A$19,topic_clusters!$A$5:$J$104,7,FALSE)+0.25*VLOOKUP($A$19,topic_clusters!$A$5:$J$104,8,FALSE)+0.2*VLOOKUP($A$19,topic_clusters!$A$5:$J$104,9,FALSE)+0.1*VLOOKUP($A$19,topic_clusters!$A$5:$J$104,10,FALSE)-10*IF(ISNUMBER(SEARCH("High",$G$19)),1,IF(ISNUMBER(SEARCH("Medium",$G$19)),0.5,0)),0))
H20: =IF($A$20="","",ROUND(0.35*VLOOKUP($A$20,topic_clusters!$A$5:$J$104,7,FALSE)+0.25*VLOOKUP($A$20,topic_clusters!$A$5:$J$104,8,FALSE)+0.2*VLOOKUP($A$20,topic_clusters!$A$5:$J$104,9,FALSE)+0.1*VLOOKUP($A$20,topic_clusters!$A$5:$J$104,10,FALSE)-10*IF(ISNUMBER(SEARCH("High",$G$20)),1,IF(ISNUMBER(SEARCH("Medium",$G$20)),0.5,0)),0))
H21: =IF($A$21="","",ROUND(0.35*VLOOKUP($A$21,topic_clusters!$A$5:$J$104,7,FALSE)+0.25*VLOOKUP($A$21,topic_clusters!$A$5:$J$104,8,FALSE)+0.2*VLOOKUP($A$21,topic_clusters!$A$5:$J$104,9,FALSE)+0.1*VLOOKUP($A$21,topic_clusters!$A$5:$J$104,10,FALSE)-10*IF(ISNUMBER(SEARCH("High",$G$21)),1,IF(ISNUMBER(SEARCH("Medium",$G$21)),0.5,0)),0))
H22: =IF($A$22="","",ROUND(0.35*VLOOKUP($A$22,topic_clusters!$A$5:$J$104,7,FALSE)+0.25*VLOOKUP($A$22,topic_clusters!$A$5:$J$104,8,FALSE)+0.2*VLOOKUP($A$22,topic_clusters!$A$5:$J$104,9,FALSE)+0.1*VLOOKUP($A$22,topic_clusters!$A$5:$J$104,10,FALSE)-10*IF(ISNUMBER(SEARCH("High",$G$22)),1,IF(ISNUMBER(SEARCH("Medium",$G$22)),0.5,0)),0))
H23: =IF($A$23="","",ROUND(0.35*VLOOKUP($A$23,topic_clusters!$A$5:$J$104,7,FALSE)+0.25*VLOOKUP($A$23,topic_clusters!$A$5:$J$104,8,FALSE)+0.2*VLOOKUP($A$23,topic_clusters!$A$5:$J$104,9,FALSE)+0.1*VLOOKUP($A$23,topic_clusters!$A$5:$J$104,10,FALSE)-10*IF(ISNUMBER(SEARCH("High",$G$23)),1,IF(ISNUMBER(SEARCH("Medium",$G$23)),0.5,0)),0))
H24: =IF($A$24="","",ROUND(0.35*VLOOKUP($A$24,topic_clusters!$A$5:$J$104,7,FALSE)+0.25*VLOOKUP($A$24,topic_clusters!$A$5:$J$104,8,FALSE)+0.2*VLOOKUP($A$24,topic_clusters!$A$5:$J$104,9,FALSE)+0.1*VLOOKUP($A$24,topic_clusters!$A$5:$J$104,10,FALSE)-10*IF(ISNUMBER(SEARCH("High",$G$24)),1,IF(ISNUMBER(SEARCH("Medium",$G$24)),0.5,0)),0))
H25: =IF($A$25="","",ROUND(0.35*VLOOKUP($A$25,topic_clusters!$A$5:$J$104,7,FALSE)+0.25*VLOOKUP($A$25,topic_clusters!$A$5:$J$104,8,FALSE)+0.2*VLOOKUP($A$25,topic_clusters!$A$5:$J$104,9,FALSE)+0.1*VLOOKUP($A$25,topic_clusters!$A$5:$J$104,10,FALSE)-10*IF(ISNUMBER(SEARCH("High",$G$25)),1,IF(ISNUMBER(SEARCH("Medium",$G$25)),0.5,0)),0))
H26: =IF($A$26="","",ROUND(0.35*VLOOKUP($A$26,topic_clusters!$A$5:$J$104,7,FALSE)+0.25*VLOOKUP($A$26,topic_clusters!$A$5:$J$104,8,FALSE)+0.2*VLOOKUP($A$26,topic_clusters!$A$5:$J$104,9,FALSE)+0.1*VLOOKUP($A$26,topic_clusters!$A$5:$J$104,10,FALSE)-10*IF(ISNUMBER(SEARCH("High",$G$26)),1,IF(ISNUMBER(SEARCH("Medium",$G$26)),0.5,0)),0))
H27: =IF($A$27="","",ROUND(0.35*VLOOKUP($A$27,topic_clusters!$A$5:$J$104,7,FALSE)+0.25*VLOOKUP($A$27,topic_clusters!$A$5:$J$104,8,FALSE)+0.2*VLOOKUP($A$27,topic_clusters!$A$5:$J$104,9,FALSE)+0.1*VLOOKUP($A$27,topic_clusters!$A$5:$J$104,10,FALSE)-10*IF(ISNUMBER(SEARCH("High",$G$27)),1,IF(ISNUMBER(SEARCH("Medium",$G$27)),0.5,0)),0))
H28: =IF($A$28="","",ROUND(0.35*VLOOKUP($A$28,topic_clusters!$A$5:$J$104,7,FALSE)+0.25*VLOOKUP($A$28,topic_clusters!$A$5:$J$104,8,FALSE)+0.2*VLOOKUP($A$28,topic_clusters!$A$5:$J$104,9,FALSE)+0.1*VLOOKUP($A$28,topic_clusters!$A$5:$J$104,10,FALSE)-10*IF(ISNUMBER(SEARCH("High",$G$28)),1,IF(ISNUMBER(SEARCH("Medium",$G$28)),0.5,0)),0))
H29: =IF($A$29="","",ROUND(0.35*VLOOKUP($A$29,topic_clusters!$A$5:$J$104,7,FALSE)+0.25*VLOOKUP($A$29,topic_clusters!$A$5:$J$104,8,FALSE)+0.2*VLOOKUP($A$29,topic_clusters!$A$5:$J$104,9,FALSE)+0.1*VLOOKUP($A$29,topic_clusters!$A$5:$J$104,10,FALSE)-10*IF(ISNUMBER(SEARCH("High",$G$29)),1,IF(ISNUMBER(SEARCH("Medium",$G$29)),0.5,0)),0))
H30: =IF($A$30="","",ROUND(0.35*VLOOKUP($A$30,topic_clusters!$A$5:$J$104,7,FALSE)+0.25*VLOOKUP($A$30,topic_clusters!$A$5:$J$104,8,FALSE)+0.2*VLOOKUP($A$30,topic_clusters!$A$5:$J$104,9,FALSE)+0.1*VLOOKUP($A$30,topic_clusters!$A$5:$J$104,10,FALSE)-10*IF(ISNUMBER(SEARCH("High",$G$30)),1,IF(ISNUMBER(SEARCH("Medium",$G$30)),0.5,0)),0))
H31: =IF($A$31="","",ROUND(0.35*VLOOKUP($A$31,topic_clusters!$A$5:$J$104,7,FALSE)+0.25*VLOOKUP($A$31,topic_clusters!$A$5:$J$104,8,FALSE)+0.2*VLOOKUP($A$31,topic_clusters!$A$5:$J$104,9,FALSE)+0.1*VLOOKUP($A$31,topic_clusters!$A$5:$J$104,10,FALSE)-10*IF(ISNUMBER(SEARCH("High",$G$31)),1,IF(ISNUMBER(SEARCH("Medium",$G$31)),0.5,0)),0))
H32: =IF($A$32="","",ROUND(0.35*VLOOKUP($A$32,topic_clusters!$A$5:$J$104,7,FALSE)+0.25*VLOOKUP($A$32,topic_clusters!$A$5:$J$104,8,FALSE)+0.2*VLOOKUP($A$32,topic_clusters!$A$5:$J$104,9,FALSE)+0.1*VLOOKUP($A$32,topic_clusters!$A$5:$J$104,10,FALSE)-10*IF(ISNUMBER(SEARCH("High",$G$32)),1,IF(ISNUMBER(SEARCH("Medium",$G$32)),0.5,0)),0))
H33: =IF($A$33="","",ROUND(0.35*VLOOKUP($A$33,topic_clusters!$A$5:$J$104,7,FALSE)+0.25*VLOOKUP($A$33,topic_clusters!$A$5:$J$104,8,FALSE)+0.2*VLOOKUP($A$33,topic_clusters!$A$5:$J$104,9,FALSE)+0.1*VLOOKUP($A$33,topic_clusters!$A$5:$J$104,10,FALSE)-10*IF(ISNUMBER(SEARCH("High",$G$33)),1,IF(ISNUMBER(SEARCH("Medium",$G$33)),0.5,0)),0))
H34: =IF($A$34="","",ROUND(0.35*VLOOKUP($A$34,topic_clusters!$A$5:$J$104,7,FALSE)+0.25*VLOOKUP($A$34,topic_clusters!$A$5:$J$104,8,FALSE)+0.2*VLOOKUP($A$34,topic_clusters!$A$5:$J$104,9,FALSE)+0.1*VLOOKUP($A$34,topic_clusters!$A$5:$J$104,10,FALSE)-10*IF(ISNUMBER(SEARCH("High",$G$34)),1,IF(ISNUMBER(SEARCH("Medium",$G$34)),0.5,0)),0))
H35: =IF($A$35="","",ROUND(0.35*VLOOKUP($A$35,topic_clusters!$A$5:$J$104,7,FALSE)+0.25*VLOOKUP($A$35,topic_clusters!$A$5:$J$104,8,FALSE)+0.2*VLOOKUP($A$35,topic_clusters!$A$5:$J$104,9,FALSE)+0.1*VLOOKUP($A$35,topic_clusters!$A$5:$J$104,10,FALSE)-10*IF(ISNUMBER(SEARCH("High",$G$35)),1,IF(ISNUMBER(SEARCH("Medium",$G$35)),0.5,0)),0))
H36: =IF($A$36="","",ROUND(0.35*VLOOKUP($A$36,topic_clusters!$A$5:$J$104,7,FALSE)+0.25*VLOOKUP($A$36,topic_clusters!$A$5:$J$104,8,FALSE)+0.2*VLOOKUP($A$36,topic_clusters!$A$5:$J$104,9,FALSE)+0.1*VLOOKUP($A$36,topic_clusters!$A$5:$J$104,10,FALSE)-10*IF(ISNUMBER(SEARCH("High",$G$36)),1,IF(ISNUMBER(SEARCH("Medium",$G$36)),0.5,0)),0))
H37: =IF($A$37="","",ROUND(0.35*VLOOKUP($A$37,topic_clusters!$A$5:$J$104,7,FALSE)+0.25*VLOOKUP($A$37,topic_clusters!$A$5:$J$104,8,FALSE)+0.2*VLOOKUP($A$37,topic_clusters!$A$5:$J$104,9,FALSE)+0.1*VLOOKUP($A$37,topic_clusters!$A$5:$J$104,10,FALSE)-10*IF(ISNUMBER(SEARCH("High",$G$37)),1,IF(ISNUMBER(SEARCH("Medium",$G$37)),0.5,0)),0))
H38: =IF($A$38="","",ROUND(0.35*VLOOKUP($A$38,topic_clusters!$A$5:$J$104,7,FALSE)+0.25*VLOOKUP($A$38,topic_clusters!$A$5:$J$104,8,FALSE)+0.2*VLOOKUP($A$38,topic_clusters!$A$5:$J$104,9,FALSE)+0.1*VLOOKUP($A$38,topic_clusters!$A$5:$J$104,10,FALSE)-10*IF(ISNUMBER(SEARCH("High",$G$38)),1,IF(ISNUMBER(SEARCH("Medium",$G$38)),0.5,0)),0))
H39: =IF($A$39="","",ROUND(0.35*VLOOKUP($A$39,topic_clusters!$A$5:$J$104,7,FALSE)+0.25*VLOOKUP($A$39,topic_clusters!$A$5:$J$104,8,FALSE)+0.2*VLOOKUP($A$39,topic_clusters!$A$5:$J$104,9,FALSE)+0.1*VLOOKUP($A$39,topic_clusters!$A$5:$J$104,10,FALSE)-10*IF(ISNUMBER(SEARCH("High",$G$39)),1,IF(ISNUMBER(SEARCH("Medium",$G$39)),0.5,0)),0))
H40: =IF($A$40="","",ROUND(0.35*VLOOKUP($A$40,topic_clusters!$A$5:$J$104,7,FALSE)+0.25*VLOOKUP($A$40,topic_clusters!$A$5:$J$104,8,FALSE)+0.2*VLOOKUP($A$40,topic_clusters!$A$5:$J$104,9,FALSE)+0.1*VLOOKUP($A$40,topic_clusters!$A$5:$J$104,10,FALSE)-10*IF(ISNUMBER(SEARCH("High",$G$40)),1,IF(ISNUMBER(SEARCH("Medium",$G$40)),0.5,0)),0))
H41: =IF($A$41="","",ROUND(0.35*VLOOKUP($A$41,topic_clusters!$A$5:$J$104,7,FALSE)+0.25*VLOOKUP($A$41,topic_clusters!$A$5:$J$104,8,FALSE)+0.2*VLOOKUP($A$41,topic_clusters!$A$5:$J$104,9,FALSE)+0.1*VLOOKUP($A$41,topic_clusters!$A$5:$J$104,10,FALSE)-10*IF(ISNUMBER(SEARCH("High",$G$41)),1,IF(ISNUMBER(SEARCH("Medium",$G$41)),0.5,0)),0))
...

Sheet weekly_watchlist
A1: weekly_watchlist
A2: 每周输出 10 个候选题材：3 个高优先级、4 个观察级、3 个风险苗头。
A4: rank | B4: week_start | C4: topic_cluster | D4: priority | E4: short_drama_genre | F4: opportunity_score | G4: platforms_seen | H4: supply_position | I4: watch_reason | J4: recommended_action | K4: owner | L4: status
A5: 1 | B5: 46182 | C5: Cheating revenge storytime | D5: =IF($C$5="","",IF($F$5>=70,"High",IF($F$5>=58,"Watch","Risk/Low"))) | E5: =IF($C$5="","",VLOOKUP($C$5,drama_angle_map!$A$5:$H$104,2,FALSE)) | F5: =IF($C$5="","",VLOOKUP($C$5,drama_angle_map!$A$5:$H$104,8,FALSE)) | G5: =IF($C$5="","",VLOOKUP($C$5,topic_clusters!$A$5:$J$104,6,FALSE)) | H5: 可跟进 | I5: 高热度+强负面情绪，短剧冲突足，现有供给可做细分差异化。 | J5: 拆 3 个英文 hook 与前 8 集节奏 | K5: 内容策略 | L5: active
A6: 2 | B6: 46182 | C6: Single mom comeback | D6: =IF($C$6="","",IF($F$6>=70,"High",IF($F$6>=58,"Watch","Risk/Low"))) | E6: =IF($C$6="","",VLOOKUP($C$6,drama_angle_map!$A$5:$H$104,2,FALSE)) | F6: =IF($C$6="","",VLOOKUP($C$6,drama_angle_map!$A$5:$H$104,8,FALSE)) | G6: =IF($C$6="","",VLOOKUP($C$6,topic_clusters!$A$5:$J$104,6,FALSE)) | H6: 可跟进 | I6: 女性逆袭与家庭伦理兼容，制作成本低，海外短剧适配度高。 | J6: 补抓 TikTok/Reddit 评论痛点 | K6: 内容策略 | L6: active
A7: 3 | B7: 46182 | C7: Toxic relationship recovery | D7: =IF($C$7="","",IF($F$7>=70,"High",IF($F$7>=58,"Watch","Risk/Low"))) | E7: =IF($C$7="","",VLOOKUP($C$7,drama_angle_map!$A$5:$H$104,2,FALSE)) | F7: =IF($C$7="","",VLOOKUP($C$7,drama_angle_map!$A$5:$H$104,8,FALSE)) | G7: =IF($C$7="","",VLOOKUP($C$7,topic_clusters!$A$5:$J$104,6,FALSE)) | H7: 差异化 | I7: 情绪强但表达需谨慎，适合女性成长+悬疑化处理。 | J7: 做风险词清单与人物设定 | K7: 内容策略 | L7: active
A8: 4 | B8: 46182 | C8: Workplace justice arc | D8: =IF($C$8="","",IF($F$8>=70,"High",IF($F$8>=58,"Watch","Risk/Low"))) | E8: =IF($C$8="","",VLOOKUP($C$8,drama_angle_map!$A$5:$H$104,2,FALSE)) | F8: =IF($C$8="","",VLOOKUP($C$8,drama_angle_map!$A$5:$H$104,8,FALSE)) | G8: =IF($C$8="","",VLOOKUP($C$8,topic_clusters!$A$5:$J$104,6,FALSE)) | H8: 观察 | I8: 社会情绪稳定，适合低成本都市爽剧，但需强化恋爱/反转钩子。 | J8: 对照职场短剧投放素材 | K8: 增长分析 | L8: watch
A9: 5 | B9: 46182 | C9: Werewolf rejected mate | D9: =IF($C$9="","",IF($F$9>=70,"High",IF($F$9>=58,"Watch","Risk/Low"))) | E9: =IF($C$9="","",VLOOKUP($C$9,drama_angle_map!$A$5:$H$104,2,FALSE)) | F9: =IF($C$9="","",VLOOKUP($C$9,drama_angle_map!$A$5:$H$104,8,FALSE)) | G9: =IF($C$9="","",VLOOKUP($C$9,topic_clusters!$A$5:$J$104,6,FALSE)) | H9: 避让/差异化 | I9: 需求耐久但供给拥挤，需要 AI/漫剧化或世界观新意。 | J9: 找新设定而非复制 alpha mate | K9: 内容策略 | L9: watch
A10: 6 | B10: 46182 | C10: Mafia forbidden romance | D10: =IF($C$10="","",IF($F$10>=70,"High",IF($F$10>=58,"Watch","Risk/Low"))) | E10: =IF($C$10="","",VLOOKUP($C$10,drama_angle_map!$A$5:$H$104,2,FALSE)) | F10: =IF($C$10="","",VLOOKUP($C$10,drama_angle_map!$A$5:$H$104,8,FALSE)) | G10: =IF($C$10="","",VLOOKUP($C$10,topic_clusters!$A$5:$J$104,6,FALSE)) | H10: 高风险观察 | I10: 禁忌恋冲突强，但暴力/胁迫风险高，适合只做弱信号追踪。 | J10: 仅收集 hook，不进入立项 | K10: 内容策略 | L10: risk_watch
D11: =IF($C$11="","",IF($F$11>=70,"High",IF($F$11>=58,"Watch","Risk/Low"))) | E11: =IF($C$11="","",VLOOKUP($C$11,drama_angle_map!$A$5:$H$104,2,FALSE)) | F11: =IF($C$11="","",VLOOKUP($C$11,drama_angle_map!$A$5:$H$104,8,FALSE)) | G11: =IF($C$11="","",VLOOKUP($C$11,topic_clusters!$A$5:$J$104,6,FALSE))
D12: =IF($C$12="","",IF($F$12>=70,"High",IF($F$12>=58,"Watch","Risk/Low"))) | E12: =IF($C$12="","",VLOOKUP($C$12,drama_angle_map!$A$5:$H$104,2,FALSE)) | F12: =IF($C$12="","",VLOOKUP($C$12,drama_angle_map!$A$5:$H$104,8,FALSE)) | G12: =IF($C$12="","",VLOOKUP($C$12,topic_clusters!$A$5:$J$104,6,FALSE))
D13: =IF($C$13="","",IF($F$13>=70,"High",IF($F$13>=58,"Watch","Risk/Low"))) | E13: =IF($C$13="","",VLOOKUP($C$13,drama_angle_map!$A$5:$H$104,2,FALSE)) | F13: =IF($C$13="","",VLOOKUP($C$13,drama_angle_map!$A$5:$H$104,8,FALSE)) | G13: =IF($C$13="","",VLOOKUP($C$13,topic_clusters!$A$5:$J$104,6,FALSE))
D14: =IF($C$14="","",IF($F$14>=70,"High",IF($F$14>=58,"Watch","Risk/Low"))) | E14: =IF($C$14="","",VLOOKUP($C$14,drama_angle_map!$A$5:$H$104,2,FALSE)) | F14: =IF($C$14="","",VLOOKUP($C$14,drama_angle_map!$A$5:$H$104,8,FALSE)) | G14: =IF($C$14="","",VLOOKUP($C$14,topic_clusters!$A$5:$J$104,6,FALSE))
D15: =IF($C$15="","",IF($F$15>=70,"High",IF($F$15>=58,"Watch","Risk/Low"))) | E15: =IF($C$15="","",VLOOKUP($C$15,drama_angle_map!$A$5:$H$104,2,FALSE)) | F15: =IF($C$15="","",VLOOKUP($C$15,drama_angle_map!$A$5:$H$104,8,FALSE)) | G15: =IF($C$15="","",VLOOKUP($C$15,topic_clusters!$A$5:$J$104,6,FALSE))
D16: =IF($C$16="","",IF($F$16>=70,"High",IF($F$16>=58,"Watch","Risk/Low"))) | E16: =IF($C$16="","",VLOOKUP($C$16,drama_angle_map!$A$5:$H$104,2,FALSE)) | F16: =IF($C$16="","",VLOOKUP($C$16,drama_angle_map!$A$5:$H$104,8,FALSE)) | G16: =IF($C$16="","",VLOOKUP($C$16,topic_clusters!$A$5:$J$104,6,FALSE))
D17: =IF($C$17="","",IF($F$17>=70,"High",IF($F$17>=58,"Watch","Risk/Low"))) | E17: =IF($C$17="","",VLOOKUP($C$17,drama_angle_map!$A$5:$H$104,2,FALSE)) | F17: =IF($C$17="","",VLOOKUP($C$17,drama_angle_map!$A$5:$H$104,8,FALSE)) | G17: =IF($C$17="","",VLOOKUP($C$17,topic_clusters!$A$5:$J$104,6,FALSE))
D18: =IF($C$18="","",IF($F$18>=70,"High",IF($F$18>=58,"Watch","Risk/Low"))) | E18: =IF($C$18="","",VLOOKUP($C$18,drama_angle_map!$A$5:$H$104,2,FALSE)) | F18: =IF($C$18="","",VLOOKUP($C$18,drama_angle_map!$A$5:$H$104,8,FALSE)) | G18: =IF($C$18="","",VLOOKUP($C$18,topic_clusters!$A$5:$J$104,6,FALSE))
D19: =IF($C$19="","",IF($F$19>=70,"High",IF($F$19>=58,"Watch","Risk/Low"))) | E19: =IF($C$19="","",VLOOKUP($C$19,drama_angle_map!$A$5:$H$104,2,FALSE)) | F19: =IF($C$19="","",VLOOKUP($C$19,drama_angle_map!$A$5:$H$104,8,FALSE)) | G19: =IF($C$19="","",VLOOKUP($C$19,topic_clusters!$A$5:$J$104,6,FALSE))
D20: =IF($C$20="","",IF($F$20>=70,"High",IF($F$20>=58,"Watch","Risk/Low"))) | E20: =IF($C$20="","",VLOOKUP($C$20,drama_angle_map!$A$5:$H$104,2,FALSE)) | F20: =IF($C$20="","",VLOOKUP($C$20,drama_angle_map!$A$5:$H$104,8,FALSE)) | G20: =IF($C$20="","",VLOOKUP($C$20,topic_clusters!$A$5:$J$104,6,FALSE))
D21: =IF($C$21="","",IF($F$21>=70,"High",IF($F$21>=58,"Watch","Risk/Low"))) | E21: =IF($C$21="","",VLOOKUP($C$21,drama_angle_map!$A$5:$H$104,2,FALSE)) | F21: =IF($C$21="","",VLOOKUP($C$21,drama_angle_map!$A$5:$H$104,8,FALSE)) | G21: =IF($C$21="","",VLOOKUP($C$21,topic_clusters!$A$5:$J$104,6,FALSE))
D22: =IF($C$22="","",IF($F$22>=70,"High",IF($F$22>=58,"Watch","Risk/Low"))) | E22: =IF($C$22="","",VLOOKUP($C$22,drama_angle_map!$A$5:$H$104,2,FALSE)) | F22: =IF($C$22="","",VLOOKUP($C$22,drama_angle_map!$A$5:$H$104,8,FALSE)) | G22: =IF($C$22="","",VLOOKUP($C$22,topic_clusters!$A$5:$J$104,6,FALSE))
D23: =IF($C$23="","",IF($F$23>=70,"High",IF($F$23>=58,"Watch","Risk/Low"))) | E23: =IF($C$23="","",VLOOKUP($C$23,drama_angle_map!$A$5:$H$104,2,FALSE)) | F23: =IF($C$23="","",VLOOKUP($C$23,drama_angle_map!$A$5:$H$104,8,FALSE)) | G23: =IF($C$23="","",VLOOKUP($C$23,topic_clusters!$A$5:$J$104,6,FALSE))
D24: =IF($C$24="","",IF($F$24>=70,"High",IF($F$24>=58,"Watch","Risk/Low"))) | E24: =IF($C$24="","",VLOOKUP($C$24,drama_angle_map!$A$5:$H$104,2,FALSE)) | F24: =IF($C$24="","",VLOOKUP($C$24,drama_angle_map!$A$5:$H$104,8,FALSE)) | G24: =IF($C$24="","",VLOOKUP($C$24,topic_clusters!$A$5:$J$104,6,FALSE))
D25: =IF($C$25="","",IF($F$25>=70,"High",IF($F$25>=58,"Watch","Risk/Low"))) | E25: =IF($C$25="","",VLOOKUP($C$25,drama_angle_map!$A$5:$H$104,2,FALSE)) | F25: =IF($C$25="","",VLOOKUP($C$25,drama_angle_map!$A$5:$H$104,8,FALSE)) | G25: =IF($C$25="","",VLOOKUP($C$25,topic_clusters!$A$5:$J$104,6,FALSE))
D26: =IF($C$26="","",IF($F$26>=70,"High",IF($F$26>=58,"Watch","Risk/Low"))) | E26: =IF($C$26="","",VLOOKUP($C$26,drama_angle_map!$A$5:$H$104,2,FALSE)) | F26: =IF($C$26="","",VLOOKUP($C$26,drama_angle_map!$A$5:$H$104,8,FALSE)) | G26: =IF($C$26="","",VLOOKUP($C$26,topic_clusters!$A$5:$J$104,6,FALSE))
D27: =IF($C$27="","",IF($F$27>=70,"High",IF($F$27>=58,"Watch","Risk/Low"))) | E27: =IF($C$27="","",VLOOKUP($C$27,drama_angle_map!$A$5:$H$104,2,FALSE)) | F27: =IF($C$27="","",VLOOKUP($C$27,drama_angle_map!$A$5:$H$104,8,FALSE)) | G27: =IF($C$27="","",VLOOKUP($C$27,topic_clusters!$A$5:$J$104,6,FALSE))
D28: =IF($C$28="","",IF($F$28>=70,"High",IF($F$28>=58,"Watch","Risk/Low"))) | E28: =IF($C$28="","",VLOOKUP($C$28,drama_angle_map!$A$5:$H$104,2,FALSE)) | F28: =IF($C$28="","",VLOOKUP($C$28,drama_angle_map!$A$5:$H$104,8,FALSE)) | G28: =IF($C$28="","",VLOOKUP($C$28,topic_clusters!$A$5:$J$104,6,FALSE))
D29: =IF($C$29="","",IF($F$29>=70,"High",IF($F$29>=58,"Watch","Risk/Low"))) | E29: =IF($C$29="","",VLOOKUP($C$29,drama_angle_map!$A$5:$H$104,2,FALSE)) | F29: =IF($C$29="","",VLOOKUP($C$29,drama_angle_map!$A$5:$H$104,8,FALSE)) | G29: =IF($C$29="","",VLOOKUP($C$29,topic_clusters!$A$5:$J$104,6,FALSE))
D30: =IF($C$30="","",IF($F$30>=70,"High",IF($F$30>=58,"Watch","Risk/Low"))) | E30: =IF($C$30="","",VLOOKUP($C$30,drama_angle_map!$A$5:$H$104,2,FALSE)) | F30: =IF($C$30="","",VLOOKUP($C$30,drama_angle_map!$A$5:$H$104,8,FALSE)) | G30: =IF($C$30="","",VLOOKUP($C$30,topic_clusters!$A$5:$J$104,6,FALSE))
D31: =IF($C$31="","",IF($F$31>=70,"High",IF($F$31>=58,"Watch","Risk/Low"))) | E31: =IF($C$31="","",VLOOKUP($C$31,drama_angle_map!$A$5:$H$104,2,FALSE)) | F31: =IF($C$31="","",VLOOKUP($C$31,drama_angle_map!$A$5:$H$104,8,FALSE)) | G31: =IF($C$31="","",VLOOKUP($C$31,topic_clusters!$A$5:$J$104,6,FALSE))
D32: =IF($C$32="","",IF($F$32>=70,"High",IF($F$32>=58,"Watch","Risk/Low"))) | E32: =IF($C$32="","",VLOOKUP($C$32,drama_angle_map!$A$5:$H$104,2,FALSE)) | F32: =IF($C$32="","",VLOOKUP($C$32,drama_angle_map!$A$5:$H$104,8,FALSE)) | G32: =IF($C$32="","",VLOOKUP($C$32,topic_clusters!$A$5:$J$104,6,FALSE))
D33: =IF($C$33="","",IF($F$33>=70,"High",IF($F$33>=58,"Watch","Risk/Low"))) | E33: =IF($C$33="","",VLOOKUP($C$33,drama_angle_map!$A$5:$H$104,2,FALSE)) | F33: =IF($C$33="","",VLOOKUP($C$33,drama_angle_map!$A$5:$H$104,8,FALSE)) | G33: =IF($C$33="","",VLOOKUP($C$33,topic_clusters!$A$5:$J$104,6,FALSE))
D34: =IF($C$34="","",IF($F$34>=70,"High",IF($F$34>=58,"Watch","Risk/Low"))) | E34: =IF($C$34="","",VLOOKUP($C$34,drama_angle_map!$A$5:$H$104,2,FALSE)) | F34: =IF($C$34="","",VLOOKUP($C$34,drama_angle_map!$A$5:$H$104,8,FALSE)) | G34: =IF($C$34="","",VLOOKUP($C$34,topic_clusters!$A$5:$J$104,6,FALSE))
D35: =IF($C$35="","",IF($F$35>=70,"High",IF($F$35>=58,"Watch","Risk/Low"))) | E35: =IF($C$35="","",VLOOKUP($C$35,drama_angle_map!$A$5:$H$104,2,FALSE)) | F35: =IF($C$35="","",VLOOKUP($C$35,drama_angle_map!$A$5:$H$104,8,FALSE)) | G35: =IF($C$35="","",VLOOKUP($C$35,topic_clusters!$A$5:$J$104,6,FALSE))
D36: =IF($C$36="","",IF($F$36>=70,"High",IF($F$36>=58,"Watch","Risk/Low"))) | E36: =IF($C$36="","",VLOOKUP($C$36,drama_angle_map!$A$5:$H$104,2,FALSE)) | F36: =IF($C$36="","",VLOOKUP($C$36,drama_angle_map!$A$5:$H$104,8,FALSE)) | G36: =IF($C$36="","",VLOOKUP($C$36,topic_clusters!$A$5:$J$104,6,FALSE))
D37: =IF($C$37="","",IF($F$37>=70,"High",IF($F$37>=58,"Watch","Risk/Low"))) | E37: =IF($C$37="","",VLOOKUP($C$37,drama_angle_map!$A$5:$H$104,2,FALSE)) | F37: =IF($C$37="","",VLOOKUP($C$37,drama_angle_map!$A$5:$H$104,8,FALSE)) | G37: =IF($C$37="","",VLOOKUP($C$37,topic_clusters!$A$5:$J$104,6,FALSE))
D38: =IF($C$38="","",IF($F$38>=70,"High",IF($F$38>=58,"Watch","Risk/Low"))) | E38: =IF($C$38="","",VLOOKUP($C$38,drama_angle_map!$A$5:$H$104,2,FALSE)) | F38: =IF($C$38="","",VLOOKUP($C$38,drama_angle_map!$A$5:$H$104,8,FALSE)) | G38: =IF($C$38="","",VLOOKUP($C$38,topic_clusters!$A$5:$J$104,6,FALSE))
D39: =IF($C$39="","",IF($F$39>=70,"High",IF($F$39>=58,"Watch","Risk/Low"))) | E39: =IF($C$39="","",VLOOKUP($C$39,drama_angle_map!$A$5:$H$104,2,FALSE)) | F39: =IF($C$39="","",VLOOKUP($C$39,drama_angle_map!$A$5:$H$104,8,FALSE)) | G39: =IF($C$39="","",VLOOKUP($C$39,topic_clusters!$A$5:$J$104,6,FALSE))
D40: =IF($C$40="","",IF($F$40>=70,"High",IF($F$40>=58,"Watch","Risk/Low"))) | E40: =IF($C$40="","",VLOOKUP($C$40,drama_angle_map!$A$5:$H$104,2,FALSE)) | F40: =IF($C$40="","",VLOOKUP($C$40,drama_angle_map!$A$5:$H$104,8,FALSE)) | G40: =IF($C$40="","",VLOOKUP($C$40,topic_clusters!$A$5:$J$104,6,FALSE))
D41: =IF($C$41="","",IF($F$41>=70,"High",IF($F$41>=58,"Watch","Risk/Low"))) | E41: =IF($C$41="","",VLOOKUP($C$41,drama_angle_map!$A$5:$H$104,2,FALSE)) | F41: =IF($C$41="","",VLOOKUP($C$41,drama_angle_map!$A$5:$H$104,8,FALSE)) | G41: =IF($C$41="","",VLOOKUP($C$41,topic_clusters!$A$5:$J$104,6,FALSE))
...

Sheet dictionary
A1: dictionary
A2: 字段字典、平台入口、评分规则和合规边界。
A4: section | B4: item | C4: value | D4: notes
A5: source_platform | B5: TikTok Creative Center | C5: 公开趋势入口 | D5: 热门 hashtag、歌曲、创作者、视频；按地区/行业/时间窗筛选。
A6: source_platform | B6: Google Trends | C6: 公开趋势/RSS | D6: Trending now 和搜索兴趣；适合捕捉泛热点。
A7: source_platform | B7: YouTube | C7: 公开 Trending/Charts | D7: 标题、分类、排名/观看趋势；不采集登录态。
A8: source_platform | B8: Reddit | C8: 公开帖子/评论讨论 | D8: 只保留公开帖链接、标题摘要、聚合互动。
A9: country_region | B9: 默认 | C9: US, UK, CA, AU | D9: 第一阶段英语市场。
A10: evidence_level | B10: A | C10: 官方/平台可核验 | D10: 平台官方页面、官方 API 或官方趋势产品。
A11: evidence_level | B11: B | C11: 公开页面可回溯 | D11: 公开网页、搜索结果、公开帖子，可人工复查。
A12: evidence_level | B12: C | C12: 弱线索待核验 | D12: 第三方转述、低可回溯线索或样本量不足。
A13: score | B13: heat_score | C13: 0-100 | D13: 热度、排名、增长速度、跨平台出现频次综合。权重 35%。
A14: score | B14: sentiment_score | C14: 0-100 | D14: 评论/讨论中的情绪强度，不等同正负面。权重 25%。
A15: score | B15: novelty_score | C15: 0-100 | D15: 相对现有短剧供给的新鲜度/差异化。权重 20%。
... A125: output_section | B125: 潜力题材 | C125: 未映射但值得观察 | D125: 来自扩展来源、暂不归入现有短剧题材簇的方向；优先做热度核验和题材转译。
